Workbook

Sheet Executive Summary
P7: Top Row KPIs | S7: KPI Tracker
P8: KPI | Q8: Value | S8: Renewal Exposure Ratio | U8: =_xlfn.XLOOKUP(S8,Table4[Key Metrics],Table4[Results],"Not Found") -> 0.88
P9: Total Leases | Q9: =COUNTA(Table1[Lease_ID]) -> 300
P10: Churn Rate | Q10: ='KPI Sheet'!B23 -> 0.33
P11: Avg Payment Delay | Q11: ='KPI Sheet'!B3 -> 12.361667
P12: Working Capital Delay | Q12: ='KPI Sheet'!B8 -> 12.484472
P13: Monthly Liquidity Oppurtunity | Q13: ='Pivot Sheet'!F7 -> 589750.25
P20: Liquidity Improvement Model | S20: Revenue Leakage Overview
P21: Metrics | Q21: Value | S21: Metric | T21: Value
P22: Current Avg Delay | Q22: =Q11 -> 12.361667 | S22: Uncollected Rent % | T22: 0.0656
P23: Target Delay (Assumption) | Q23: 6 | S23: Under-Market Portfolio Impact | T23: 0.1317
P24: Improvement % | Q24: =(Q22-Q23)/Q22 -> 0.51462856 | S24: Underpriced Properties | T24: 225
P25: Monthly Liquidity Freed | Q25: =GETPIVOTDATA("Sum of Due_Amount",'Pivot Sheet'!$A$3)*(Q22-Q23)/30 -> 589750.25 | S25: WC Delay Index | T25: 0.1011
P26: Revenue at 8+ Day Risk | Q26: =SUM(GETPIVOTDATA("Sum of Due_Amount",'Pivot Sheet'!$A$3,"Delay_Risk_Bucket","Medium Risk(8-15)"),GETPIVOTDATA("Sum of Due_Amount",'Pivot Sheet'!$A$3,"Delay_Risk_Bucket","High Risk(16-30)"))/GETPIVOTDATA("Sum of Due_Amount",'Pivot Sheet'!$A$3) -> 0.69733366
T35: Operation Risk Table
T36: Risk Area | U36: Status
T37: Expiry Exposure | U37: 0.88
T38: Escalation Consistency | U38: 56% Below Expected
T39: Maintenance Concentration | U39: 22.64% (Top 10%)
T40: Highest Cost Driver | U40: HVAC (29%)
O48: Scenario | P48: Result
O49: Delay Reduced to 6 Days | P49: 51% Faster Cycle
O50: Monthly Liquidity Freed | P50: ₹5.9 Lakhs
O51: Annual Liquidity Gain | P51: ₹70.8 Lakhs

Sheet KPI Sheet
A2: Key Metrics | B2: Results
A3: Average Delay | B3: =AVERAGE(Table2[[#All],[Delay_Days]]) -> 12.361667
A4: % Payment Late | B4: =COUNTIF(Table2[Delay_Days],">0")/COUNT(Table2[[#All],[Delay_Days]]) -> 0.94333333
A5: % Payments Late > 7 Days | B5: =COUNTIF(Table2[Delay_Days],">7")/COUNT(Table2[[#All],[Delay_Days]]) -> 0.68833333
A6: % Payments Late > 15 Days | B6: =COUNTIF(Table2[Delay_Days],">15")/COUNT(Table2[[#All],[Delay_Days]]) -> 0.37333333
A7: Total WC Blocked | B7: =SUM(Table2[WC_Blocked]) -> 34720716
A8: WC Locked Period | B8: =SUM(Table2[WC_Blocked])/SUM(Table2[[#All],[Due_Amount]]) -> 12.484472
A9: WC Delay Index | B9: =SUM(Table2[[#All],[Due_Amount]])/SUM(Table2[[#All],[Payment_Date]]) -> 0.10110968
A10: Total Rent Billed | B10: =SUM(Table2[[#All],[Due_Amount]]) -> 2781112
A11: Total Outstandind Rent | B11: =SUM(Table2[Outstanding_Amount]) -> 182472
A12: Total Uncollected Rent % | B12: =B11/B10 -> 0.065611166
A13: Leakage Calculations | B13: =SUM(Table2[[#All],[Leakage Calculations]]) -> 366266.39
A14: Number of Underpriced Property | B14: =COUNTIF(Table2[Under_Market_Flag],"Underpriced") -> 225
A15: Average Portfolio Rent | B15: =Rent_Collections!J2 -> 4635.1867
A16: Porfolio Imapct % | B16: =B13/SUM(Table2[Due_Amount]) -> 0.13169782
A17: Average Renewal Lag | B17: =AVERAGEIF(Table1[[#All],[Renewal_Status]],"Expired",Table1[[#All],[Days_After_Expiry]]) -> 416.19192
A18: Renewal Lag % | B18: =COUNTIF(Table1[[#All],[Renewal_Status]],"Expired")/COUNTA(Table1[Lease_ID]) -> 0.33
A19: Renewal Exposure Ratio | B19: =SUM(GETPIVOTDATA("Lease_ID",'Pivot Sheet'!$A$21,"Expiry_Risk_Category","Expired"),GETPIVOTDATA("Lease_ID",'Pivot Sheet'!$A$21,"Expiry_Risk_Category","High Risk"),GETPIVOTDATA("Lease_ID",'Pivot Sheet'!$A$21,"Expiry_Risk_Category","Medium Risk"))/GETPIVOTDATA("Lease_ID",'Pivot Sheet'!$A$21) -> 0.88
A20: Average Escalation Accuracy | B20: =AVERAGEIF(Table1[[#All],[Escalation_Accuracy_%]],">0") -> 1.0581193
A21: Process Failure Rate | B21: =COUNTIF(Table1[Escalation_Accuracy_%],"<1")/COUNT(Table1[Escalation_Accuracy_%]) -> 0.56321839
A22: Expired Lease | B22: =COUNTIF(Table1[[#All],[Renewal_Status]],"Expired") -> 99
A23: Tenant Churn Rate | B23: =B22/GETPIVOTDATA("Lease_ID",'Pivot Sheet'!$A$21) -> 0.33
A24: Active Stability Ratio | B24: =1-B23 -> 0.67
A25: Top 10% Property Count | B25: =ROUNDUP(0.1*'Pivot Sheet'!B168,0) -> 14
A26: Top 10% Property Cost (M) | B26: =SUM('Pivot Sheet'!B30:B43) -> 1209682
A27: Cost Contentration % (M) | B27: =B26/GETPIVOTDATA("Cost",'Pivot Sheet'!$A$29) -> 0.22636159

Sheet Pivot Sheet
B2: Revenue Exposure | E2: Liquidity Improvement Model
A3: Risk_Bucket | B3: Number of Payments | C3: Sum of Due_Amount | E3: Metrics | F3: Value
A4: High Risk(16-30) | B4: 224 | C4: 1050564 | E4: Current Avg Delay | F4: ='KPI Sheet'!B3 -> 12.361667
A5: Low Risk(1-7) | B5: 153 | C5: 682734 | E5: Target Delay (Assumption) | F5: 6
A6: Medium Risk(8-15) | B6: 189 | C6: 888799 | E6: Improvement % | F6: =(F4-F5)/F4 -> 0.51462856
A7: On Time | B7: 34 | C7: 159015 | E7: Monthly Liquidity Freed | F7: =GETPIVOTDATA("Sum of Due_Amount",'Pivot Sheet'!$A$3)*(F4-F5)/30 -> 589750.25
A8: Grand Total | B8: 600 | C8: 2781112 | E8: Revenue at 8+ Day Risk | F8: =SUM(GETPIVOTDATA("Sum of Due_Amount",'Pivot Sheet'!$A$3,"Delay_Risk_Bucket","Medium Risk(8-15)"),GETPIVOTDATA("Sum of Due_Amount",'Pivot Sheet'!$A$3,"Delay_Risk_Bucket","High Risk(16-30)"))/GETPIVOTDATA("Sum of Due_Amount",'Pivot Sheet'!$A$3) -> 0.69733366
A12: Revenue Leakage Heatmap
A13: Risk_Bucket | B13: Sum of Outstanding_Amount
A14: High Risk(16-30) | B14: 105910
A15: Low Risk(1-7) | B15: 0
A16: Medium Risk(8-15) | B16: 76562
A17: On Time | B17: 0
A18: Grand Total | B18: 182472
A20: Expiry Risk Pivot
A21: Row Labels | B21: Count of Lease_ID
A22: Expired | B22: 251
A23: High Risk | B23: 8
A24: Medium Risk | B24: 5
A25: Safe | B25: 36
A26: Grand Total | B26: 300
A27: Renewal Exposure Ratio | B27: ='KPI Sheet'!B19 -> 0.88
G28: Cost Per Issue Type
A29: Property_ID | B29: Total_Maintenance_Cost | D29: Row Labels | E29: Sum of Cost | F29: Average of Resolution_Days
A30: P112 | B30: 113176 | D30: HVAC | E30: 1548600 | F30: 11.25
A31: P010 | B31: 111495 | D31: Plumbing | E31: 1346177 | F31: 10.686869
A32: P049 | B32: 102600 | D32: Structural | E32: 1225060 | F32: 10.838384
A33: P037 | B33: 95877 | D33: Electrical | E33: 1224188 | F33: 10.066667
A34: P077 | B34: 89504 | D34: Grand Total | E34: 5344025 | F34: 10.7425
A35: P023 | B35: 82153
A36: P016 | B36: 81721
A37: P081 | B37: 80276 | F37: Vendor Camparison
A38: P040 | B38: 79452 | D38: Vendor_Name | E38: Count of Jobs | F38: Sum of Cost | G38: Average of Resolution_Days | I38: Vendor_Name | J38: Cost/Job
A39: P091 | B39: 77014 | D39: Vendor A | E39: 147 | F39: 1994939 | G39: 10.945578 | I39: Vendor A | J39: =GETPIVOTDATA("Sum of Cost",$D$38,"Vendor","Vendor A")/GETPIVOTDATA("Count of Jobs",$D$38,"Vendor","Vendor A") -> 13571.014
A40: P030 | B40: 76172 | D40: Vendor B | E40: 145 | F40: 1924973 | G40: 10.703448 | I40: Vendor B | J40: =GETPIVOTDATA("Sum of Cost",$D$38,"Vendor","Vendor B")/GETPIVOTDATA("Count of Jobs",$D$38,"Vendor","Vendor B") -> 13275.676
A41: P113 | B41: 75055 | D41: Vendor C | E41: 108 | F41: 1424113 | G41: 10.518519 | I41: Vendor C | J41: =GETPIVOTDATA("Sum of Cost",$D$38,"Vendor","Vendor C")/GETPIVOTDATA("Count of Jobs",$D$38,"Vendor","Vendor C") -> 13186.231
A42: P005 | B42: 72887 | D42: Grand Total | E42: 400 | F42: 5344025 | G42: 10.7425
A43: P064 | B43: 72300
A44: P038 | B44: 72010 | I44: Vendor_Name | J44: Cost Share
A45: P025 | B45: 69704 | I45: Vendor A | J45: =GETPIVOTDATA("Sum of Cost",$D$38,"Vendor","Vendor A")/GETPIVOTDATA("Sum of Cost",$D$38) -> 0.37330271
...

Sheet Lease_Tracking
A1: Lease_ID | B1: Property_ID | C1: Tenant_ID | D1: Lease_Start | E1: Lease_End | F1: Monthly_Rent | G1: Security_Deposit | H1: Escalation_% | I1: Previous_Rent | J1: Expected_Rent | K1: Escalation_Accuracy_% | L1: Renewal_Status | M1: Days_After_Expiry | N1: Days_to_Expiry | O1: Expiry_Risk_Category
A2: L247 | B2: P001 | C2: T247 | D2: 44870 | E2: 45965 | F2: 6375 | G2: 5680 | H2: 5.24 | I2: =IF(B2=B1, F1, "") | J2: =IF(I2<>"", I2*(1+H2/100), "") | K2: =IF(Table1[[#This Row],[Expected_Rent]]<>"", F2/Table1[[#This Row],[Expected_Rent]], "") | L2: Expired | M2: =IF(Table1[[#This Row],[Renewal_Status]]="Expired",TODAY()-Table1[[#This Row],[Lease_End]],0) -> 102 | N2: =Table1[[#This Row],[Lease_End]]-TODAY() -> -102 | O2: =IF(Table1[[#This Row],[Days_to_Expiry]]<0,"Expired", IF(Table1[[#This Row],[Days_to_Expiry]]<30,"High Risk", IF(Table1[[#This Row],[Days_to_Expiry]]<=60,"Medium Risk", "Safe"))) -> Expired
A3: L221 | B3: P002 | C3: T221 | D3: 44631 | E3: 45361 | F3: 3762 | G3: 11569 | H3: 5.8 | I3: =IF(B3=B2, F2, "") | J3: =IF(I3<>"", I3*(1+H3/100), "") | K3: =IF(Table1[[#This Row],[Expected_Rent]]<>"", F3/Table1[[#This Row],[Expected_Rent]], "") | L3: Renewed | M3: =IF(Table1[[#This Row],[Renewal_Status]]="Expired",TODAY()-Table1[[#This Row],[Lease_End]],0) -> 0 | N3: =Table1[[#This Row],[Lease_End]]-TODAY() -> -706 | O3: =IF(Table1[[#This Row],[Days_to_Expiry]]<0,"Expired", IF(Table1[[#This Row],[Days_to_Expiry]]<30,"High Risk", IF(Table1[[#This Row],[Days_to_Expiry]]<=60,"Medium Risk", "Safe"))) -> Expired
A4: L134 | B4: P002 | C4: T134 | D4: 45079 | E4: 45809 | F4: 2704 | G4: 14539 | H4: 6.58 | I4: =IF(B4=B3, F3, "") -> 3762 | J4: =IF(I4<>"", I4*(1+H4/100), "") -> 4009.5396 | K4: =IF(Table1[[#This Row],[Expected_Rent]]<>"", F4/Table1[[#This Row],[Expected_Rent]], "") -> 0.67439164 | L4: Expired | M4: =IF(Table1[[#This Row],[Renewal_Status]]="Expired",TODAY()-Table1[[#This Row],[Lease_End]],0) -> 258 | N4: =Table1[[#This Row],[Lease_End]]-TODAY() -> -258 | O4: =IF(Table1[[#This Row],[Days_to_Expiry]]<0,"Expired", IF(Table1[[#This Row],[Days_to_Expiry]]<30,"High Risk", IF(Table1[[#This Row],[Days_to_Expiry]]<=60,"Medium Risk", "Safe"))) -> Expired
A5: L178 | B5: P003 | C5: T178 | D5: 44735 | E5: 45830 | F5: 6048 | G5: 19594 | H5: 4.98 | I5: =IF(B5=B4, F4, "") | J5: =IF(I5<>"", I5*(1+H5/100), "") | K5: =IF(Table1[[#This Row],[Expected_Rent]]<>"", F5/Table1[[#This Row],[Expected_Rent]], "") | L5: Renewed | M5: =IF(Table1[[#This Row],[Renewal_Status]]="Expired",TODAY()-Table1[[#This Row],[Lease_End]],0) -> 0 | N5: =Table1[[#This Row],[Lease_End]]-TODAY() -> -237 | O5: =IF(Table1[[#This Row],[Days_to_Expiry]]<0,"Expired", IF(Table1[[#This Row],[Days_to_Expiry]]<30,"High Risk", IF(Table1[[#This Row],[Days_to_Expiry]]<=60,"Medium Risk", "Safe"))) -> Expired
A6: L208 | B6: P003 | C6: T208 | D6: 44765 | E6: 45130 | F6: 2215 | G6: 15222 | H6: 3.2 | I6: =IF(B6=B5, F5, "") -> 6048 | J6: =IF(I6<>"", I6*(1+H6/100), "") -> 6241.536 | K6: =IF(Table1[[#This Row],[Expected_Rent]]<>"", F6/Table1[[#This Row],[Expected_Rent]], "") -> 0.35488059 | L6: Active | M6: =IF(Table1[[#This Row],[Renewal_Status]]="Expired",TODAY()-Table1[[#This Row],[Lease_End]],0) -> 0 | N6: =Table1[[#This Row],[Lease_End]]-TODAY() -> -937 | O6: =IF(Table1[[#This Row],[Days_to_Expiry]]<0,"Expired", IF(Table1[[#This Row],[Days_to_Expiry]]<30,"High Risk", IF(Table1[[#This Row],[Days_to_Expiry]]<=60,"Medium Risk", "Safe"))) -> Expired
A7: L198 | B7: P003 | C7: T198 | D7: 44839 | E7: 45204 | F7: 3587 | G7: 16207 | H7: 3.11 | I7: =IF(B7=B6, F6, "") -> 2215 | J7: =IF(I7<>"", I7*(1+H7/100), "") -> 2283.8865 | K7: =IF(Table1[[#This Row],[Expected_Rent]]<>"", F7/Table1[[#This Row],[Expected_Rent]], "") -> 1.5705684 | L7: Renewed | M7: =IF(Table1[[#This Row],[Renewal_Status]]="Expired",TODAY()-Table1[[#This Row],[Lease_End]],0) -> 0 | N7: =Table1[[#This Row],[Lease_End]]-TODAY() -> -863 | O7: =IF(Table1[[#This Row],[Days_to_Expiry]]<0,"Expired", IF(Table1[[#This Row],[Days_to_Expiry]]<30,"High Risk", IF(Table1[[#This Row],[Days_to_Expiry]]<=60,"Medium Risk", "Safe"))) -> Expired
A8: L269 | B8: P003 | C8: T269 | D8: 45019 | E8: 45384 | F8: 4290 | G8: 15770 | H8: 3.04 | I8: =IF(B8=B7, F7, "") -> 3587 | J8: =IF(I8<>"", I8*(1+H8/100), "") -> 3696.0448 | K8: =IF(Table1[[#This Row],[Expected_Rent]]<>"", F8/Table1[[#This Row],[Expected_Rent]], "") -> 1.1607002 | L8: Renewed | M8: =IF(Table1[[#This Row],[Renewal_Status]]="Expired",TODAY()-Table1[[#This Row],[Lease_End]],0) -> 0 | N8: =Table1[[#This Row],[Lease_End]]-TODAY() -> -683 | O8: =IF(Table1[[#This Row],[Days_to_Expiry]]<0,"Expired", IF(Table1[[#This Row],[Days_to_Expiry]]<30,"High Risk", IF(Table1[[#This Row],[Days_to_Expiry]]<=60,"Medium Risk", "Safe"))) -> Expired
A9: L102 | B9: P004 | C9: T102 | D9: 44598 | E9: 45328 | F9: 3091 | G9: 16523 | H9: 3.88 | I9: =IF(B9=B8, F8, "") | J9: =IF(I9<>"", I9*(1+H9/100), "") | K9: =IF(Table1[[#This Row],[Expected_Rent]]<>"", F9/Table1[[#This Row],[Expected_Rent]], "") | L9: Renewed | M9: =IF(Table1[[#This Row],[Renewal_Status]]="Expired",TODAY()-Table1[[#This Row],[Lease_End]],0) -> 0 | N9: =Table1[[#This Row],[Lease_End]]-TODAY() -> -739 | O9: =IF(Table1[[#This Row],[Days_to_Expiry]]<0,"Expired", IF(Table1[[#This Row],[Days_to_Expiry]]<30,"High Risk", IF(Table1[[#This Row],[Days_to_Expiry]]<=60,"Medium Risk", "Safe"))) -> Expired
A10: L144 | B10: P004 | C10: T144 | D10: 44673 | E10: 45038 | F10: 4147 | G10: 6423 | H10: 4.01 | I10: =IF(B10=B9, F9, "") -> 3091 | J10: =IF(I10<>"", I10*(1+H10/100), "") -> 3214.9491 | K10: =IF(Table1[[#This Row],[Expected_Rent]]<>"", F10/Table1[[#This Row],[Expected_Rent]], "") -> 1.2899116 | L10: Expired | M10: =IF(Table1[[#This Row],[Renewal_Status]]="Expired",TODAY()-Table1[[#This Row],[Lease_End]],0) -> 1029 | N10: =Table1[[#This Row],[Lease_End]]-TODAY() -> -1029 | O10: =IF(Table1[[#This Row],[Days_to_Expiry]]<0,"Expired", IF(Table1[[#This Row],[Days_to_Expiry]]<30,"High Risk", IF(Table1[[#This Row],[Days_to_Expiry]]<=60,"Medium Risk", "Safe"))) -> Expired
A11: L027 | B11: P004 | C11: T027 | D11: 45037 | E11: 46132 | F11: 4208 | G11: 5643 | H11: 4.84 | I11: =IF(B11=B10, F10, "") -> 4147 | J11: =IF(I11<>"", I11*(1+H11/100), "") -> 4347.7148 | K11: =IF(Table1[[#This Row],[Expected_Rent]]<>"", F11/Table1[[#This Row],[Expected_Rent]], "") -> 0.96786477 | L11: Expired | M11: =IF(Table1[[#This Row],[Renewal_Status]]="Expired",TODAY()-Table1[[#This Row],[Lease_End]],0) -> -65 | N11: =Table1[[#This Row],[Lease_End]]-TODAY() -> 65 | O11: =IF(Table1[[#This Row],[Days_to_Expiry]]<0,"Expired", IF(Table1[[#This Row],[Days_to_Expiry]]<30,"High Risk", IF(Table1[[#This Row],[Days_to_Expiry]]<=60,"Medium Risk", "Safe"))) -> Safe
A12: L179 | B12: P004 | C12: T179 | D12: 45153 | E12: 45518 | F12: 3379 | G12: 12160 | H12: 3.74 | I12: =IF(B12=B11, F11, "") -> 4208 | J12: =IF(I12<>"", I12*(1+H12/100), "") -> 4365.3792 | K12: =IF(Table1[[#This Row],[Expected_Rent]]<>"", F12/Table1[[#This Row],[Expected_Rent]], "") -> 0.77404501 | L12: Renewed | M12: =IF(Table1[[#This Row],[Renewal_Status]]="Expired",TODAY()-Table1[[#This Row],[Lease_End]],0) -> 0 | N12: =Table1[[#This Row],[Lease_End]]-TODAY() -> -549 | O12: =IF(Table1[[#This Row],[Days_to_Expiry]]<0,"Expired", IF(Table1[[#This Row],[Days_to_Expiry]]<30,"High Risk", IF(Table1[[#This Row],[Days_to_Expiry]]<=60,"Medium Risk", "Safe"))) -> Expired
A13: L138 | B13: P005 | C13: T138 | D13: 44897 | E13: 45627 | F13: 2346 | G13: 5409 | H13: 5.4 | I13: =IF(B13=B12, F12, "") | J13: =IF(I13<>"", I13*(1+H13/100), "") | K13: =IF(Table1[[#This Row],[Expected_Rent]]<>"", F13/Table1[[#This Row],[Expected_Rent]], "") | L13: Active | M13: =IF(Table1[[#This Row],[Renewal_Status]]="Expired",TODAY()-Table1[[#This Row],[Lease_End]],0) -> 0 | N13: =Table1[[#This Row],[Lease_End]]-TODAY() -> -440 | O13: =IF(Table1[[#This Row],[Days_to_Expiry]]<0,"Expired", IF(Table1[[#This Row],[Days_to_Expiry]]<30,"High Risk", IF(Table1[[#This Row],[Days_to_Expiry]]<=60,"Medium Risk", "Safe"))) -> Expired
... A23: L117 | B23: P009 | C23: T117 | D23: 44843 | E23: 45573 | F23: 2111 | G23: 18134 | H23: 3.32 | I23: =IF(B23=B22, F22, "") | J23: =IF(I23<>"", I23*(1+H23/100), "") | K23: =IF(Table1[[#This Row],[Expected_Rent]]<>"", F23/Table1[[#This Row],[Expected_Rent]], "") | L23: Expired | M23: =IF(Table1[[#This Row],[Renewal_Status]]="Expired",TODAY()-Table1[[#This Row],[Lease_End]],0) -> 494 | N23: =Table1[[#This Row],[Lease_End]]-TODAY() -> -494 | O23: =IF(Table1[[#This Row],[Days_to_Expiry]]<0,"Expired", IF(Table1[[#This Row],[Days_to_Expiry]]<30,"High Risk", IF(Table1[[#This Row],[Days_to_Expiry]]<=60,"Medium Risk", "Safe"))) -> Expired
A24: L298 | B24: P009 | C24: T298 | D24: 45147 | E24: 45877 | F24: 4757 | G24: 13927 | H24: 7.69 | I24: =IF(B24=B23, F23, "") -> 2111 | J24: =IF(I24<>"", I24*(1+H24/100), "") -> 2273.3359 | K24: =IF(Table1[[#This Row],[Expected_Rent]]<>"", F24/Table1[[#This Row],[Expected_Rent]], "") -> 2.0925196 | L24: Active | M24: =IF(Table1[[#This Row],[Renewal_Status]]="Expired",TODAY()-Table1[[#This Row],[Lease_End]],0) -> 0 | N24: =Table1[[#This Row],[Lease_End]]-TODAY() -> -190 | O24: =IF(Table1[[#This Row],[Days_to_Expiry]]<0,"Expired", IF(Table1[[#This Row],[Days_to_Expiry]]<30,"High Risk", IF(Table1[[#This Row],[Days_to_Expiry]]<=60,"Medium Risk", "Safe"))) -> Expired | S24: to expiry
A25: L216 | B25: P009 | C25: T216 | D25: 45222 | E25: 45952 | F25: 4857 | G25: 10510 | H25: 3.56 | I25: =IF(B25=B24, F24, "") -> 4757 | J25: =IF(I25<>"", I25*(1+H25/100), "") -> 4926.3492 | K25: =IF(Table1[[#This Row],[Expected_Rent]]<>"", F25/Table1[[#This Row],[Expected_Rent]], "") -> 0.9859228 | L25: Expired | M25: =IF(Table1[[#This Row],[Renewal_Status]]="Expired",TODAY()-Table1[[#This Row],[Lease_End]],0) -> 115 | N25: =Table1[[#This Row],[Lease_End]]-TODAY() -> -115 | O25: =IF(Table1[[#This Row],[Days_to_Expiry]]<0,"Expired", IF(Table1[[#This Row],[Days_to_Expiry]]<30,"High Risk", IF(Table1[[#This Row],[Days_to_Expiry]]<=60,"Medium Risk", "Safe"))) -> Expired
A26: L011 | B26: P009 | C26: T011 | D26: 45253 | E26: 45618 | F26: 3950 | G26: 19450 | H26: 7.08 | I26: =IF(B26=B25, F25, "") -> 4857 | J26: =IF(I26<>"", I26*(1+H26/100), "") -> 5200.8756 | K26: =IF(Table1[[#This Row],[Expected_Rent]]<>"", F26/Table1[[#This Row],[Expected_Rent]], "") -> 0.7594875 | L26: Active | M26: =IF(Table1[[#This Row],[Renewal_Status]]="Expired",TODAY()-Table1[[#This Row],[Lease_End]],0) -> 0 | N26: =Table1[[#This Row],[Lease_End]]-TODAY() -> -449 | O26: =IF(Table1[[#This Row],[Days_to_Expiry]]<0,"Expired", IF(Table1[[#This Row],[Days_to_Expiry]]<30,"High Risk", IF(Table1[[#This Row],[Days_to_Expiry]]<=60,"Medium Risk", "Safe"))) -> Expired
A27: L116 | B27: P010 | C27: T116 | D27: 44895 | E27: 45260 | F27: 4475 | G27: 12995 | H27: 6.01 | I27: =IF(B27=B26, F26, "") | J27: =IF(I27<>"", I27*(1+H27/100), "") | K27: =IF(Table1[[#This Row],[Expected_Rent]]<>"", F27/Table1[[#This Row],[Expected_Rent]], "") | L27: Expired | M27: =IF(Table1[[#This Row],[Renewal_Status]]="Expired",TODAY()-Table1[[#This Row],[Lease_End]],0) -> 807 | N27: =Table1[[#This Row],[Lease_End]]-TODAY() -> -807 | O27: =IF(Table1[[#This Row],[Days_to_Expiry]]<0,"Expired", IF(Table1[[#This Row],[Days_to_Expiry]]<30,"High Risk", IF(Table1[[#This Row],[Days_to_Expiry]]<=60,"Medium Risk", "Safe"))) -> Expired
A28: L220 | B28: P010 | C28: T220 | D28: 45074 | E28: 45804 | F28: 2655 | G28: 7574 | H28: 6.85 | I28: =IF(B28=B27, F27, "") -> 4475 | J28: =IF(I28<>"", I28*(1+H28/100), "") -> 4781.5375 | K28: =IF(Table1[[#This Row],[Expected_Rent]]<>"", F28/Table1[[#This Row],[Expected_Rent]], "") -> 0.55526073 | L28: Renewed | M28: =IF(Table1[[#This Row],[Renewal_Status]]="Expired",TODAY()-Table1[[#This Row],[Lease_End]],0) -> 0 | N28: =Table1[[#This Row],[Lease_End]]-TODAY() -> -263 | O28: =IF(Table1[[#This Row],[Days_to_Expiry]]<0,"Expired", IF(Table1[[#This Row],[Days_to_Expiry]]<30,"High Risk", IF(Table1[[#This Row],[Days_to_Expiry]]<=60,"Medium Risk", "Safe"))) -> Expired
A29: L141 | B29: P010 | C29: T141 | D29: 45170 | E29: 46265 | F29: 3733 | G29: 17022 | H29: 3.7 | I29: =IF(B29=B28, F28, "") -> 2655 | J29: =IF(I29<>"", I29*(1+H29/100), "") -> 2753.235 | K29: =IF(Table1[[#This Row],[Expected_Rent]]<>"", F29/Table1[[#This Row],[Expected_Rent]], "") -> 1.3558596 | L29: Expired | M29: =IF(Table1[[#This Row],[Renewal_Status]]="Expired",TODAY()-Table1[[#This Row],[Lease_End]],0) -> -198 | N29: =Table1[[#This Row],[Lease_End]]-TODAY() -> 198 | O29: =IF(Table1[[#This Row],[Days_to_Expiry]]<0,"Expired", IF(Table1[[#This Row],[Days_to_Expiry]]<30,"High Risk", IF(Table1[[#This Row],[Days_to_Expiry]]<=60,"Medium Risk", "Safe"))) -> Safe
A30: L100 | B30: P011 | C30: T100 | D30: 44636 | E30: 45731 | F30: 3482 | G30: 17210 | H30: 6.76 | I30: =IF(B30=B29, F29, "") | J30: =IF(I30<>"", I30*(1+H30/100), "") | K30: =IF(Table1[[#This Row],[Expected_Rent]]<>"", F30/Table1[[#This Row],[Expected_Rent]], "") | L30: Active | M30: =IF(Table1[[#This Row],[Renewal_Status]]="Expired",TODAY()-Table1[[#This Row],[Lease_End]],0) -> 0 | N30: =Table1[[#This Row],[Lease_End]]-TODAY() -> -336 | O30: =IF(Table1[[#This Row],[Days_to_Expiry]]<0,"Expired", IF(Table1[[#This Row],[Days_to_Expiry]]<30,"High Risk", IF(Table1[[#This Row],[Days_to_Expiry]]<=60,"Medium Risk", "Safe"))) -> Expired
A31: L272 | B31: P011 | C31: T272 | D31: 45023 | E31: 45753 | F31: 2708 | G31: 5158 | H31: 4.82 | I31: =IF(B31=B30, F30, "") -> 3482 | J31: =IF(I31<>"", I31*(1+H31/100), "") -> 3649.8324 | K31: =IF(Table1[[#This Row],[Expected_Rent]]<>"", F31/Table1[[#This Row],[Expected_Rent]], "") -> 0.74195188 | L31: Active | M31: =IF(Table1[[#This Row],[Renewal_Status]]="Expired",TODAY()-Table1[[#This Row],[Lease_End]],0) -> 0 | N31: =Table1[[#This Row],[Lease_End]]-TODAY() -> -314 | O31: =IF(Table1[[#This Row],[Days_to_Expiry]]<0,"Expired", IF(Table1[[#This Row],[Days_to_Expiry]]<30,"High Risk", IF(Table1[[#This Row],[Days_to_Expiry]]<=60,"Medium Risk", "Safe"))) -> Expired
A32: L054 | B32: P011 | C32: T054 | D32: 45166 | E32: 46261 | F32: 6918 | G32: 13212 | H32: 4.86 | I32: =IF(B32=B31, F31, "") -> 2708 | J32: =IF(I32<>"", I32*(1+H32/100), "") -> 2839.6088 | K32: =IF(Table1[[#This Row],[Expected_Rent]]<>"", F32/Table1[[#This Row],[Expected_Rent]], "") -> 2.4362511 | L32: Expired | M32: =IF(Table1[[#This Row],[Renewal_Status]]="Expired",TODAY()-Table1[[#This Row],[Lease_End]],0) -> -194 | N32: =Table1[[#This Row],[Lease_End]]-TODAY() -> 194 | O32: =IF(Table1[[#This Row],[Days_to_Expiry]]<0,"Expired", IF(Table1[[#This Row],[Days_to_Expiry]]<30,"High Risk", IF(Table1[[#This Row],[Days_to_Expiry]]<=60,"Medium Risk", "Safe"))) -> Safe
A33: L131 | B33: P012 | C33: T131 | D33: 44915 | E33: 46010 | F33: 3240 | G33: 6861 | H33: 5.92 | I33: =IF(B33=B32, F32, "") | J33: =IF(I33<>"", I33*(1+H33/100), "") | K33: =IF(Table1[[#This Row],[Expected_Rent]]<>"", F33/Table1[[#This Row],[Expected_Rent]], "") | L33: Renewed | M33: =IF(Table1[[#This Row],[Renewal_Status]]="Expired",TODAY()-Table1[[#This Row],[Lease_End]],0) -> 0 | N33: =Table1[[#This Row],[Lease_End]]-TODAY() -> -57 | O33: =IF(Table1[[#This Row],[Days_to_Expiry]]<0,"Expired", IF(Table1[[#This Row],[Days_to_Expiry]]<30,"High Risk", IF(Table1[[#This Row],[Days_to_Expiry]]<=60,"Medium Risk", "Safe"))) -> Expired
A34: L050 | B34: P013 | C34: T050 | D34: 45116 | E34: 45846 | F34: 3381 | G34: 6856 | H34: 3.81 | I34: =IF(B34=B33, F33, "") | J34: =IF(I34<>"", I34*(1+H34/100), "") | K34: =IF(Table1[[#This Row],[Expected_Rent]]<>"", F34/Table1[[#This Row],[Expected_Rent]], "") | L34: Expired | M34: =IF(Table1[[#This Row],[Renewal_Status]]="Expired",TODAY()-Table1[[#This Row],[Lease_End]],0) -> 221 | N34: =Table1[[#This Row],[Lease_End]]-TODAY() -> -221 | O34: =IF(Table1[[#This Row],[Days_to_Expiry]]<0,"Expired", IF(Table1[[#This Row],[Days_to_Expiry]]<30,"High Risk", IF(Table1[[#This Row],[Days_to_Expiry]]<=60,"Medium Risk", "Safe"))) -> Expired
A35: L143 | B35: P013 | C35: T143 | D35: 45196 | E35: 45561 | F35: 3374 | G35: 17067 | H35: 4.74 | I35: =IF(B35=B34, F34, "") -> 3381 | J35: =IF(I35<>"", I35*(1+H35/100), "") -> 3541.2594 | K35: =IF(Table1[[#This Row],[Expected_Rent]]<>"", F35/Table1[[#This Row],[Expected_Rent]], "") -> 0.95276839 | L35: Active | M35: =IF(Table1[[#This Row],[Renewal_Status]]="Expired",TODAY()-Table1[[#This Row],[Lease_End]],0) -> 0 | N35: =Table1[[#This Row],[Lease_End]]-TODAY() -> -506 | O35: =IF(Table1[[#This Row],[Days_to_Expiry]]<0,"Expired", IF(Table1[[#This Row],[Days_to_Expiry]]<30,"High Risk", IF(Table1[[#This Row],[Days_to_Expiry]]<=60,"Medium Risk", "Safe"))) -> Expired
A36: L155 | B36: P014 | C36: T155 | D36: 44904 | E36: 45634 | F36: 5085 | G36: 6979 | H36: 4.77 | I36: =IF(B36=B35, F35, "") | J36: =IF(I36<>"", I36*(1+H36/100), "") | K36: =IF(Table1[[#This Row],[Expected_Rent]]<>"", F36/Table1[[#This Row],[Expected_Rent]], "") | L36: Expired | M36: =IF(Table1[[#This Row],[Renewal_Status]]="Expired",TODAY()-Table1[[#This Row],[Lease_End]],0) -> 433 | N36: =Table1[[#This Row],[Lease_End]]-TODAY() -> -433 | O36: =IF(Table1[[#This Row],[Days_to_Expiry]]<0,"Expired", IF(Table1[[#This Row],[Days_to_Expiry]]<30,"High Risk", IF(Table1[[#This Row],[Days_to_Expiry]]<=60,"Medium Risk", "Safe"))) -> Expired
... A301: L230 | B301: P150 | C301: T230 | D301: 44619 | E301: 44984 | F301: 6540 | G301: 14319 | H301: 6.12 | I301: =IF(B301=B300, F300, "") -> 3658 | J301: =IF(I301<>"", I301*(1+H301/100), "") -> 3881.8696 | K301: =IF(Table1[[#This Row],[Expected_Rent]]<>"", F301/Table1[[#This Row],[Expected_Rent]], "") -> 1.6847552 | L301: Renewed | M301: =IF(Table1[[#This Row],[Renewal_Status]]="Expired",TODAY()-Table1[[#This Row],[Lease_End]],0) -> 0 | N301: =Table1[[#This Row],[Lease_End]]-TODAY() -> -1083 | O301: =IF(Table1[[#This Row],[Days_to_Expiry]]<0,"Expired", IF(Table1[[#This Row],[Days_to_Expiry]]<30,"High Risk", IF(Table1[[#This Row],[Days_to_Expiry]]<=60,"Medium Risk", "Safe"))) -> Expired

Sheet Rent_Collections
A1: Tenant_ID | B1: Month | C1: Due_Amount | D1: Paid_Amount | E1: Outstanding_Amount | F1: Payment_Date | G1: Delay_Days | H1: WC_Blocked | I1: Delay_Risk_Bucket | J1: Estimated_Market_Rent | K1: Current Rent Gap | L1: Under_Market % | M1: Under_Market_Flag | N1: Leakage Calculations
A2: T167 | B2: 2025-05 | C2: 5348 | D2: 5348 | E2: =Table2[[#This Row],[Due_Amount]]-Table2[[#This Row],[Paid_Amount]] -> 0 | F2: 45859 | G2: 3 | H2: =Table2[[#This Row],[Due_Amount]]*Table2[[#This Row],[Delay_Days]] -> 16044 | I2: =IF(Table2[[#This Row],[Delay_Days]]=0,"On Time",IF(Table2[[#This Row],[Delay_Days]]<=7,"Low Risk(1-7)",IF(Table2[[#This Row],[Delay_Days]]<=15,"Medium Risk(8-15)",IF(Table2[[#This Row],[Delay_Days]]<=30,"High Risk(16-30)","Severe Risk(30+)")))) -> Low Risk(1-7) | J2: =AVERAGE(Table2[Due_Amount]) -> 4635.1867 | K2: =Table2[[#This Row],[Estimated_Market_Rent]]-Table2[[#This Row],[Due_Amount]] -> -712.81333 | L2: =IF(Table2[[#This Row],[Current Rent Gap]]>0,Table2[[#This Row],[Current Rent Gap]]/Table2[[#This Row],[Estimated_Market_Rent]],0) -> 0 | M2: =IF(Table2[[#This Row],[Under_Market %]]>0.1,"Underpriced","OK") -> OK | N2: =SUMIFS(Table2[[#This Row],[Current Rent Gap]],Table2[[#This Row],[Current Rent Gap]],">0") -> 0
A3: T023 | B3: 2025-01 | C3: 5995 | D3: 5538 | E3: =Table2[[#This Row],[Due_Amount]]-Table2[[#This Row],[Paid_Amount]] -> 457 | F3: 45949 | G3: 12 | H3: =Table2[[#This Row],[Due_Amount]]*Table2[[#This Row],[Delay_Days]] -> 71940 | I3: =IF(Table2[[#This Row],[Delay_Days]]=0,"On Time",IF(Table2[[#This Row],[Delay_Days]]<=7,"Low Risk(1-7)",IF(Table2[[#This Row],[Delay_Days]]<=15,"Medium Risk(8-15)",IF(Table2[[#This Row],[Delay_Days]]<=30,"High Risk(16-30)","Severe Risk(30+)")))) -> Medium Risk(8-15) | J3: =AVERAGE(Table2[Due_Amount]) -> 4635.1867 | K3: =Table2[[#This Row],[Estimated_Market_Rent]]-Table2[[#This Row],[Due_Amount]] -> -1359.8133 | L3: =IF(Table2[[#This Row],[Current Rent Gap]]>0,Table2[[#This Row],[Current Rent Gap]]/Table2[[#This Row],[Estimated_Market_Rent]],0) -> 0 | M3: =IF(Table2[[#This Row],[Under_Market %]]>0.1,"Underpriced","OK") -> OK | N3: =SUMIFS(Table2[[#This Row],[Current Rent Gap]],Table2[[#This Row],[Current Rent Gap]],">0") -> 0
A4: T091 | B4: 2025-07 | C4: 6229 | D4: 5932 | E4: =Table2[[#This Row],[Due_Amount]]-Table2[[#This Row],[Paid_Amount]] -> 297 | F4: 45877 | G4: 23 | H4: =Table2[[#This Row],[Due_Amount]]*Table2[[#This Row],[Delay_Days]] -> 143267 | I4: =IF(Table2[[#This Row],[Delay_Days]]=0,"On Time",IF(Table2[[#This Row],[Delay_Days]]<=7,"Low Risk(1-7)",IF(Table2[[#This Row],[Delay_Days]]<=15,"Medium Risk(8-15)",IF(Table2[[#This Row],[Delay_Days]]<=30,"High Risk(16-30)","Severe Risk(30+)")))) -> High Risk(16-30) | J4: =AVERAGE(Table2[Due_Amount]) -> 4635.1867 | K4: =Table2[[#This Row],[Estimated_Market_Rent]]-Table2[[#This Row],[Due_Amount]] -> -1593.8133 | L4: =IF(Table2[[#This Row],[Current Rent Gap]]>0,Table2[[#This Row],[Current Rent Gap]]/Table2[[#This Row],[Estimated_Market_Rent]],0) -> 0 | M4: =IF(Table2[[#This Row],[Under_Market %]]>0.1,"Underpriced","OK") -> OK | N4: =SUMIFS(Table2[[#This Row],[Current Rent Gap]],Table2[[#This Row],[Current Rent Gap]],">0") -> 0
A5: T120 | B5: 2025-10 | C5: 2720 | D5: 1870 | E5: =Table2[[#This Row],[Due_Amount]]-Table2[[#This Row],[Paid_Amount]] -> 850 | F5: 45844 | G5: 14 | H5: =Table2[[#This Row],[Due_Amount]]*Table2[[#This Row],[Delay_Days]] -> 38080 | I5: =IF(Table2[[#This Row],[Delay_Days]]=0,"On Time",IF(Table2[[#This Row],[Delay_Days]]<=7,"Low Risk(1-7)",IF(Table2[[#This Row],[Delay_Days]]<=15,"Medium Risk(8-15)",IF(Table2[[#This Row],[Delay_Days]]<=30,"High Risk(16-30)","Severe Risk(30+)")))) -> Medium Risk(8-15) | J5: =AVERAGE(Table2[Due_Amount]) -> 4635.1867 | K5: =Table2[[#This Row],[Estimated_Market_Rent]]-Table2[[#This Row],[Due_Amount]] -> 1915.1867 | L5: =IF(Table2[[#This Row],[Current Rent Gap]]>0,Table2[[#This Row],[Current Rent Gap]]/Table2[[#This Row],[Estimated_Market_Rent]],0) -> 0.41318437 | M5: =IF(Table2[[#This Row],[Under_Market %]]>0.1,"Underpriced","OK") -> Underpriced | N5: =SUMIFS(Table2[[#This Row],[Current Rent Gap]],Table2[[#This Row],[Current Rent Gap]],">0") -> 1915.1867 | P5: =SUM(Table2[[#All],[Current Rent Gap]]) -> 4.0017767e-11
A6: T078 | B6: 2025-12 | C6: 4248 | D6: 3532 | E6: =Table2[[#This Row],[Due_Amount]]-Table2[[#This Row],[Paid_Amount]] -> 716 | F6: 45661 | G6: 25 | H6: =Table2[[#This Row],[Due_Amount]]*Table2[[#This Row],[Delay_Days]] -> 106200 | I6: =IF(Table2[[#This Row],[Delay_Days]]=0,"On Time",IF(Table2[[#This Row],[Delay_Days]]<=7,"Low Risk(1-7)",IF(Table2[[#This Row],[Delay_Days]]<=15,"Medium Risk(8-15)",IF(Table2[[#This Row],[Delay_Days]]<=30,"High Risk(16-30)","Severe Risk(30+)")))) -> High Risk(16-30) | J6: =AVERAGE(Table2[Due_Amount]) -> 4635.1867 | K6: =Table2[[#This Row],[Estimated_Market_Rent]]-Table2[[#This Row],[Due_Amount]] -> 387.18667 | L6: =IF(Table2[[#This Row],[Current Rent Gap]]>0,Table2[[#This Row],[Current Rent Gap]]/Table2[[#This Row],[Estimated_Market_Rent]],0) -> 0.083532055 | M6: =IF(Table2[[#This Row],[Under_Market %]]>0.1,"Underpriced","OK") -> OK | N6: =SUMIFS(Table2[[#This Row],[Current Rent Gap]],Table2[[#This Row],[Current Rent Gap]],">0") -> 387.18667 | P6: =SUM(Table2[Current Rent Gap]) -> 4.0017767e-11
A7: T261 | B7: 2025-09 | C7: 6634 | D7: 6622 | E7: =Table2[[#This Row],[Due_Amount]]-Table2[[#This Row],[Paid_Amount]] -> 12 | F7: 45926 | G7: 16 | H7: =Table2[[#This Row],[Due_Amount]]*Table2[[#This Row],[Delay_Days]] -> 106144 | I7: =IF(Table2[[#This Row],[Delay_Days]]=0,"On Time",IF(Table2[[#This Row],[Delay_Days]]<=7,"Low Risk(1-7)",IF(Table2[[#This Row],[Delay_Days]]<=15,"Medium Risk(8-15)",IF(Table2[[#This Row],[Delay_Days]]<=30,"High Risk(16-30)","Severe Risk(30+)")))) -> High Risk(16-30) | J7: =AVERAGE(Table2[Due_Amount]) -> 4635.1867 | K7: =Table2[[#This Row],[Estimated_Market_Rent]]-Table2[[#This Row],[Due_Amount]] -> -1998.8133 | L7: =IF(Table2[[#This Row],[Current Rent Gap]]>0,Table2[[#This Row],[Current Rent Gap]]/Table2[[#This Row],[Estimated_Market_Rent]],0) -> 0 | M7: =IF(Table2[[#This Row],[Under_Market %]]>0.1,"Underpriced","OK") -> OK | N7: =SUMIFS(Table2[[#This Row],[Current Rent Gap]],Table2[[#This Row],[Current Rent Gap]],">0") -> 0 | P7: =SUM(Table2[[#All],[Current Rent Gap]]) -> 4.0017767e-11
A8: T138 | B8: 2025-06 | C8: 4029 | D8: 3445 | E8: =Table2[[#This Row],[Due_Amount]]-Table2[[#This Row],[Paid_Amount]] -> 584 | F8: 45956 | G8: 24 | H8: =Table2[[#This Row],[Due_Amount]]*Table2[[#This Row],[Delay_Days]] -> 96696 | I8: =IF(Table2[[#This Row],[Delay_Days]]=0,"On Time",IF(Table2[[#This Row],[Delay_Days]]<=7,"Low Risk(1-7)",IF(Table2[[#This Row],[Delay_Days]]<=15,"Medium Risk(8-15)",IF(Table2[[#This Row],[Delay_Days]]<=30,"High Risk(16-30)","Severe Risk(30+)")))) -> High Risk(16-30) | J8: =AVERAGE(Table2[Due_Amount]) -> 4635.1867 | K8: =Table2[[#This Row],[Estimated_Market_Rent]]-Table2[[#This Row],[Due_Amount]] -> 606.18667 | L8: =IF(Table2[[#This Row],[Current Rent Gap]]>0,Table2[[#This Row],[Current Rent Gap]]/Table2[[#This Row],[Estimated_Market_Rent]],0) -> 0.13077934 | M8: =IF(Table2[[#This Row],[Under_Market %]]>0.1,"Underpriced","OK") -> Underpriced | N8: =SUMIFS(Table2[[#This Row],[Current Rent Gap]],Table2[[#This Row],[Current Rent Gap]],">0") -> 606.18667
A9: T287 | B9: 2025-07 | C9: 5965 | D9: 5188 | E9: =Table2[[#This Row],[Due_Amount]]-Table2[[#This Row],[Paid_Amount]] -> 777 | F9: 45665 | G9: 12 | H9: =Table2[[#This Row],[Due_Amount]]*Table2[[#This Row],[Delay_Days]] -> 71580 | I9: =IF(Table2[[#This Row],[Delay_Days]]=0,"On Time",IF(Table2[[#This Row],[Delay_Days]]<=7,"Low Risk(1-7)",IF(Table2[[#This Row],[Delay_Days]]<=15,"Medium Risk(8-15)",IF(Table2[[#This Row],[Delay_Days]]<=30,"High Risk(16-30)","Severe Risk(30+)")))) -> Medium Risk(8-15) | J9: =AVERAGE(Table2[Due_Amount]) -> 4635.1867 | K9: =Table2[[#This Row],[Estimated_Market_Rent]]-Table2[[#This Row],[Due_Amount]] -> -1329.8133 | L9: =IF(Table2[[#This Row],[Current Rent Gap]]>0,Table2[[#This Row],[Current Rent Gap]]/Table2[[#This Row],[Estimated_Market_Rent]],0) -> 0 | M9: =IF(Table2[[#This Row],[Under_Market %]]>0.1,"Underpriced","OK") -> OK | N9: =SUMIFS(Table2[[#This Row],[Current Rent Gap]],Table2[[#This Row],[Current Rent Gap]],">0") -> 0
A10: T132 | B10: 2025-09 | C10: 2716 | D10: 2668 | E10: =Table2[[#This Row],[Due_Amount]]-Table2[[#This Row],[Paid_Amount]] -> 48 | F10: 45737 | G10: 24 | H10: =Table2[[#This Row],[Due_Amount]]*Table2[[#This Row],[Delay_Days]] -> 65184 | I10: =IF(Table2[[#This Row],[Delay_Days]]=0,"On Time",IF(Table2[[#This Row],[Delay_Days]]<=7,"Low Risk(1-7)",IF(Table2[[#This Row],[Delay_Days]]<=15,"Medium Risk(8-15)",IF(Table2[[#This Row],[Delay_Days]]<=30,"High Risk(16-30)","Severe Risk(30+)")))) -> High Risk(16-30) | J10: =AVERAGE(Table2[Due_Amount]) -> 4635.1867 | K10: =Table2[[#This Row],[Estimated_Market_Rent]]-Table2[[#This Row],[Due_Amount]] -> 1919.1867 | L10: =IF(Table2[[#This Row],[Current Rent Gap]]>0,Table2[[#This Row],[Current Rent Gap]]/Table2[[#This Row],[Estimated_Market_Rent]],0) -> 0.41404733 | M10: =IF(Table2[[#This Row],[Under_Market %]]>0.1,"Underpriced","OK") -> Underpriced | N10: =SUMIFS(Table2[[#This Row],[Current Rent Gap]],Table2[[#This Row],[Current Rent Gap]],">0") -> 1919.1867
A11: T042 | B11: 2025-02 | C11: 5095 | D11: 4128 | E11: =Table2[[#This Row],[Due_Amount]]-Table2[[#This Row],[Paid_Amount]] -> 967 | F11: 45847 | G11: 23 | H11: =Table2[[#This Row],[Due_Amount]]*Table2[[#This Row],[Delay_Days]] -> 117185 | I11: =IF(Table2[[#This Row],[Delay_Days]]=0,"On Time",IF(Table2[[#This Row],[Delay_Days]]<=7,"Low Risk(1-7)",IF(Table2[[#This Row],[Delay_Days]]<=15,"Medium Risk(8-15)",IF(Table2[[#This Row],[Delay_Days]]<=30,"High Risk(16-30)","Severe Risk(30+)")))) -> High Risk(16-30) | J11: =AVERAGE(Table2[Due_Amount]) -> 4635.1867 | K11: =Table2[[#This Row],[Estimated_Market_Rent]]-Table2[[#This Row],[Due_Amount]] -> -459.81333 | L11: =IF(Table2[[#This Row],[Current Rent Gap]]>0,Table2[[#This Row],[Current Rent Gap]]/Table2[[#This Row],[Estimated_Market_Rent]],0) -> 0 | M11: =IF(Table2[[#This Row],[Under_Market %]]>0.1,"Underpriced","OK") -> OK | N11: =SUMIFS(Table2[[#This Row],[Current Rent Gap]],Table2[[#This Row],[Current Rent Gap]],">0") -> 0
A12: T211 | B12: 2025-04 | C12: 2052 | D12: 2052 | E12: =Table2[[#This Row],[Due_Amount]]-Table2[[#This Row],[Paid_Amount]] -> 0 | F12: 45700 | G12: 0 | H12: =Table2[[#This Row],[Due_Amount]]*Table2[[#This Row],[Delay_Days]] -> 0 | I12: =IF(Table2[[#This Row],[Delay_Days]]=0,"On Time",IF(Table2[[#This Row],[Delay_Days]]<=7,"Low Risk(1-7)",IF(Table2[[#This Row],[Delay_Days]]<=15,"Medium Risk(8-15)",IF(Table2[[#This Row],[Delay_Days]]<=30,"High Risk(16-30)","Severe Risk(30+)")))) -> On Time | J12: =AVERAGE(Table2[Due_Amount]) -> 4635.1867 | K12: =Table2[[#This Row],[Estimated_Market_Rent]]-Table2[[#This Row],[Due_Amount]] -> 2583.1867 | L12: =IF(Table2[[#This Row],[Current Rent Gap]]>0,Table2[[#This Row],[Current Rent Gap]]/Table2[[#This Row],[Estimated_Market_Rent]],0) -> 0.55729938 | M12: =IF(Table2[[#This Row],[Under_Market %]]>0.1,"Underpriced","OK") -> Underpriced | N12: =SUMIFS(Table2[[#This Row],[Current Rent Gap]],Table2[[#This Row],[Current Rent Gap]],">0") -> 2583.1867
A13: T136 | B13: 2025-07 | C13: 5412 | D13: 5412 | E13: =Table2[[#This Row],[Due_Amount]]-Table2[[#This Row],[Paid_Amount]] -> 0 | F13: 45723 | G13: 6 | H13: =Table2[[#This Row],[Due_Amount]]*Table2[[#This Row],[Delay_Days]] -> 32472 | I13: =IF(Table2[[#This Row],[Delay_Days]]=0,"On Time",IF(Table2[[#This Row],[Delay_Days]]<=7,"Low Risk(1-7)",IF(Table2[[#This Row],[Delay_Days]]<=15,"Medium Risk(8-15)",IF(Table2[[#This Row],[Delay_Days]]<=30,"High Risk(16-30)","Severe Risk(30+)")))) -> Low Risk(1-7) | J13: =AVERAGE(Table2[Due_Amount]) -> 4635.1867 | K13: =Table2[[#This Row],[Estimated_Market_Rent]]-Table2[[#This Row],[Due_Amount]] -> -776.81333 | L13: =IF(Table2[[#This Row],[Current Rent Gap]]>0,Table2[[#This Row],[Current Rent Gap]]/Table2[[#This Row],[Estimated_Market_Rent]],0) -> 0 | M13: =IF(Table2[[#This Row],[Under_Market %]]>0.1,"Underpriced","OK") -> OK | N13: =SUMIFS(Table2[[#This Row],[Current Rent Gap]],Table2[[#This Row],[Current Rent Gap]],">0") -> 0
A14: T077 | B14: 2025-05 | C14: 3722 | D14: 3532 | E14: =Table2[[#This Row],[Due_Amount]]-Table2[[#This Row],[Paid_Amount]] -> 190 | F14: 45967 | G14: 21 | H14: =Table2[[#This Row],[Due_Amount]]*Table2[[#This Row],[Delay_Days]] -> 78162 | I14: =IF(Table2[[#This Row],[Delay_Days]]=0,"On Time",IF(Table2[[#This Row],[Delay_Days]]<=7,"Low Risk(1-7)",IF(Table2[[#This Row],[Delay_Days]]<=15,"Medium Risk(8-15)",IF(Table2[[#This Row],[Delay_Days]]<=30,"High Risk(16-30)","Severe Risk(30+)")))) -> High Risk(16-30) | J14: =AVERAGE(Table2[Due_Amount]) -> 4635.1867 | K14: =Table2[[#This Row],[Estimated_Market_Rent]]-Table2[[#This Row],[Due_Amount]] -> 913.18667 | L14: =IF(Table2[[#This Row],[Current Rent Gap]]>0,Table2[[#This Row],[Current Rent Gap]]/Table2[[#This Row],[Estimated_Market_Rent]],0) -> 0.19701184 | M14: =IF(Table2[[#This Row],[Under_Market %]]>0.1,"Underpriced","OK") -> Underpriced | N14: =SUMIFS(Table2[[#This Row],[Current Rent Gap]],Table2[[#This Row],[Current Rent Gap]],">0") -> 913.18667
A15: T097 | B15: 2025-07 | C15: 4264 | D15: 4264 | E15: =Table2[[#This Row],[Due_Amount]]-Table2[[#This Row],[Paid_Amount]] -> 0 | F15: 45957 | G15: 6 | H15: =Table2[[#This Row],[Due_Amount]]*Table2[[#This Row],[Delay_Days]] -> 25584 | I15: =IF(Table2[[#This Row],[Delay_Days]]=0,"On Time",IF(Table2[[#This Row],[Delay_Days]]<=7,"Low Risk(1-7)",IF(Table2[[#This Row],[Delay_Days]]<=15,"Medium Risk(8-15)",IF(Table2[[#This Row],[Delay_Days]]<=30,"High Risk(16-30)","Severe Risk(30+)")))) -> Low Risk(1-7) | J15: =AVERAGE(Table2[Due_Amount]) -> 4635.1867 | K15: =Table2[[#This Row],[Estimated_Market_Rent]]-Table2[[#This Row],[Due_Amount]] -> 371.18667 | L15: =IF(Table2[[#This Row],[Current Rent Gap]]>0,Table2[[#This Row],[Current Rent Gap]]/Table2[[#This Row],[Estimated_Market_Rent]],0) -> 0.080080198 | M15: =IF(Table2[[#This Row],[Under_Market %]]>0.1,"Underpriced","OK") -> OK | N15: =SUMIFS(Table2[[#This Row],[Current Rent Gap]],Table2[[#This Row],[Current Rent Gap]],">0") -> 371.18667
A16: T130 | B16: 2025-12 | C16: 5047 | D16: 5047 | E16: =Table2[[#This Row],[Due_Amount]]-Table2[[#This Row],[Paid_Amount]] -> 0 | F16: 45894 | G16: 9 | H16: =Table2[[#This Row],[Due_Amount]]*Table2[[#This Row],[Delay_Days]] -> 45423 | I16: =IF(Table2[[#This Row],[Delay_Days]]=0,"On Time",IF(Table2[[#This Row],[Delay_Days]]<=7,"Low Risk(1-7)",IF(Table2[[#This Row],[Delay_Days]]<=15,"Medium Risk(8-15)",IF(Table2[[#This Row],[Delay_Days]]<=30,"High Risk(16-30)","Severe Risk(30+)")))) -> Medium Risk(8-15) | J16: =AVERAGE(Table2[Due_Amount]) -> 4635.1867 | K16: =Table2[[#This Row],[Estimated_Market_Rent]]-Table2[[#This Row],[Due_Amount]] -> -411.81333 | L16: =IF(Table2[[#This Row],[Current Rent Gap]]>0,Table2[[#This Row],[Current Rent Gap]]/Table2[[#This Row],[Estimated_Market_Rent]],0) -> 0 | M16: =IF(Table2[[#This Row],[Under_Market %]]>0.1,"Underpriced","OK") -> OK | N16: =SUMIFS(Table2[[#This Row],[Current Rent Gap]],Table2[[#This Row],[Current Rent Gap]],">0") -> 0
A17: T131 | B17: 2025-06 | C17: 2140 | D17: 2140 | E17: =Table2[[#This Row],[Due_Amount]]-Table2[[#This Row],[Paid_Amount]] -> 0 | F17: 45816 | G17: 0 | H17: =Table2[[#This Row],[Due_Amount]]*Table2[[#This Row],[Delay_Days]] -> 0 | I17: =IF(Table2[[#This Row],[Delay_Days]]=0,"On Time",IF(Table2[[#This Row],[Delay_Days]]<=7,"Low Risk(1-7)",IF(Table2[[#This Row],[Delay_Days]]<=15,"Medium Risk(8-15)",IF(Table2[[#This Row],[Delay_Days]]<=30,"High Risk(16-30)","Severe Risk(30+)")))) -> On Time | J17: =AVERAGE(Table2[Due_Amount]) -> 4635.1867 | K17: =Table2[[#This Row],[Estimated_Market_Rent]]-Table2[[#This Row],[Due_Amount]] -> 2495.1867 | L17: =IF(Table2[[#This Row],[Current Rent Gap]]>0,Table2[[#This Row],[Current Rent Gap]]/Table2[[#This Row],[Estimated_Market_Rent]],0) -> 0.53831417 | M17: =IF(Table2[[#This Row],[Under_Market %]]>0.1,"Underpriced","OK") -> Underpriced | N17: =SUMIFS(Table2[[#This Row],[Current Rent Gap]],Table2[[#This Row],[Current Rent Gap]],">0") -> 2495.1867
A18: T208 | B18: 2025-02 | C18: 4324 | D18: 3959 | E18: =Table2[[#This Row],[Due_Amount]]-Table2[[#This Row],[Paid_Amount]] -> 365 | F18: 45919 | G18: 17 | H18: =Table2[[#This Row],[Due_Amount]]*Table2[[#This Row],[Delay_Days]] -> 73508 | I18: =IF(Table2[[#This Row],[Delay_Days]]=0,"On Time",IF(Table2[[#This Row],[Delay_Days]]<=7,"Low Risk(1-7)",IF(Table2[[#This Row],[Delay_Days]]<=15,"Medium Risk(8-15)",IF(Table2[[#This Row],[Delay_Days]]<=30,"High Risk(16-30)","Severe Risk(30+)")))) -> High Risk(16-30) | J18: =AVERAGE(Table2[Due_Amount]) -> 4635.1867 | K18: =Table2[[#This Row],[Estimated_Market_Rent]]-Table2[[#This Row],[Due_Amount]] -> 311.18667 | L18: =IF(Table2[[#This Row],[Current Rent Gap]]>0,Table2[[#This Row],[Current Rent Gap]]/Table2[[#This Row],[Estimated_Market_Rent]],0) -> 0.067135736 | M18: =IF(Table2[[#This Row],[Under_Market %]]>0.1,"Underpriced","OK") -> OK | N18: =SUMIFS(Table2[[#This Row],[Current Rent Gap]],Table2[[#This Row],[Current Rent Gap]],">0") -> 311.18667
A19: T101 | B19: 2025-07 | C19: 5814 | D19: 5250 | E19: =Table2[[#This Row],[Due_Amount]]-Table2[[#This Row],[Paid_Amount]] -> 564 | F19: 45699 | G19: 13 | H19: =Table2[[#This Row],[Due_Amount]]*Table2[[#This Row],[Delay_Days]] -> 75582 | I19: =IF(Table2[[#This Row],[Delay_Days]]=0,"On Time",IF(Table2[[#This Row],[Delay_Days]]<=7,"Low Risk(1-7)",IF(Table2[[#This Row],[Delay_Days]]<=15,"Medium Risk(8-15)",IF(Table2[[#This Row],[Delay_Days]]<=30,"High Risk(16-30)","Severe Risk(30+)")))) -> Medium Risk(8-15) | J19: =AVERAGE(Table2[Due_Amount]) -> 4635.1867 | K19: =Table2[[#This Row],[Estimated_Market_Rent]]-Table2[[#This Row],[Due_Amount]] -> -1178.8133 | L19: =IF(Table2[[#This Row],[Current Rent Gap]]>0,Table2[[#This Row],[Current Rent Gap]]/Table2[[#This Row],[Estimated_Market_Rent]],0) -> 0 | M19: =IF(Table2[[#This Row],[Under_Market %]]>0.1,"Underpriced","OK") -> OK | N19: =SUMIFS(Table2[[#This Row],[Current Rent Gap]],Table2[[#This Row],[Current Rent Gap]],">0") -> 0
... A601: T101 | B601: 2025-03 | C601: 6185 | D601: 5927 | E601: =Table2[[#This Row],[Due_Amount]]-Table2[[#This Row],[Paid_Amount]] -> 258 | F601: 45824 | G601: 10 | H601: =Table2[[#This Row],[Due_Amount]]*Table2[[#This Row],[Delay_Days]] -> 61850 | I601: =IF(Table2[[#This Row],[Delay_Days]]=0,"On Time",IF(Table2[[#This Row],[Delay_Days]]<=7,"Low Risk(1-7)",IF(Table2[[#This Row],[Delay_Days]]<=15,"Medium Risk(8-15)",IF(Table2[[#This Row],[Delay_Days]]<=30,"High Risk(16-30)","Severe Risk(30+)")))) -> Medium Risk(8-15) | J601: =AVERAGE(Table2[Due_Amount]) -> 4635.1867 | K601: =Table2[[#This Row],[Estimated_Market_Rent]]-Table2[[#This Row],[Due_Amount]] -> -1549.8133 | L601: =IF(Table2[[#This Row],[Current Rent Gap]]>0,Table2[[#This Row],[Current Rent Gap]]/Table2[[#This Row],[Estimated_Market_Rent]],0) -> 0 | M601: =IF(Table2[[#This Row],[Under_Market %]]>0.1,"Underpriced","OK") -> OK | N601: =SUMIFS(Table2[[#This Row],[Current Rent Gap]],Table2[[#This Row],[Current Rent Gap]],">0") -> 0

Sheet Maintenance_Log
A1: Property_ID | B1: Request_Date | C1: Issue_Type | D1: Vendor | E1: Cost | F1: Resolution_Days
A2: P135 | B2: 45999 | C2: Electrical | D2: Vendor B | E2: 11818 | F2: 16
A3: P016 | B3: 45839 | C3: HVAC | D3: Vendor B | E3: 18584 | F3: 17
A4: P058 | B4: 45666 | C4: HVAC | D4: Vendor C | E4: 3646 | F4: 17
A5: P045 | B5: 45862 | C5: Structural | D5: Vendor A | E5: 14282 | F5: 9
A6: P038 | B6: 45829 | C6: HVAC | D6: Vendor B | E6: 11484 | F6: 4
A7: P055 | B7: 45860 | C7: Electrical | D7: Vendor B | E7: 17888 | F7: 3
A8: P091 | B8: 45922 | C8: Electrical | D8: Vendor B | E8: 3185 | F8: 9
A9: P081 | B9: 45704 | C9: HVAC | D9: Vendor B | E9: 4708 | F9: 9
A10: P133 | B10: 45698 | C10: Electrical | D10: Vendor C | E10: 11453 | F10: 7
A11: P047 | B11: 45912 | C11: Plumbing | D11: Vendor C | E11: 23017 | F11: 20
A12: P117 | B12: 45780 | C12: HVAC | D12: Vendor A | E12: 15381 | F12: 2
A13: P015 | B13: 45741 | C13: Structural | D13: Vendor A | E13: 19545 | F13: 3
... A401: P126 | B401: 45875 | C401: Structural | D401: Vendor B | E401: 11270 | F401: 10
